[2025-03-11T18:59:05.991+0000] {taskinstance.py:1083} INFO - Dependencies all met for <TaskInstance: project2.transfer_backup manual__2025-03-11T18:58:55.020908+00:00 [queued]>
[2025-03-11T18:59:06.006+0000] {taskinstance.py:1083} INFO - Dependencies all met for <TaskInstance: project2.transfer_backup manual__2025-03-11T18:58:55.020908+00:00 [queued]>
[2025-03-11T18:59:06.006+0000] {taskinstance.py:1279} INFO - 
--------------------------------------------------------------------------------
[2025-03-11T18:59:06.007+0000] {taskinstance.py:1280} INFO - Starting attempt 1 of 1
[2025-03-11T18:59:06.007+0000] {taskinstance.py:1281} INFO - 
--------------------------------------------------------------------------------
[2025-03-11T18:59:06.020+0000] {taskinstance.py:1300} INFO - Executing <Task(SSHOperator): transfer_backup> on 2025-03-11 18:58:55.020908+00:00
[2025-03-11T18:59:06.025+0000] {standard_task_runner.py:55} INFO - Started process 16054 to run task
[2025-03-11T18:59:06.029+0000] {standard_task_runner.py:82} INFO - Running: ['***', 'tasks', 'run', 'project2', 'transfer_backup', 'manual__2025-03-11T18:58:55.020908+00:00', '--job-id', '320', '--raw', '--subdir', 'DAGS_FOLDER/project2.py', '--cfg-path', '/tmp/tmpkwxy8kdz']
[2025-03-11T18:59:06.029+0000] {standard_task_runner.py:83} INFO - Job 320: Subtask transfer_backup
[2025-03-11T18:59:06.100+0000] {task_command.py:388} INFO - Running <TaskInstance: project2.transfer_backup manual__2025-03-11T18:58:55.020908+00:00 [running]> on host 2ec744569db4
[2025-03-11T18:59:06.173+0000] {taskinstance.py:1509} INFO - Exporting the following env vars:
AIRFLOW_CTX_DAG_OWNER=***
AIRFLOW_CTX_DAG_ID=project2
AIRFLOW_CTX_TASK_ID=transfer_backup
AIRFLOW_CTX_EXECUTION_DATE=2025-03-11T18:58:55.020908+00:00
AIRFLOW_CTX_TRY_NUMBER=1
AIRFLOW_CTX_DAG_RUN_ID=manual__2025-03-11T18:58:55.020908+00:00
[2025-03-11T18:59:06.173+0000] {ssh.py:133} INFO - Creating ssh_client
[2025-03-11T18:59:06.207+0000] {ssh.py:111} INFO - ssh_hook is not provided or invalid. Trying ssh_conn_id to create SSHHook.
[2025-03-11T18:59:06.216+0000] {base.py:73} INFO - Using connection ID 'ssh_vm' for task execution.
[2025-03-11T18:59:06.217+0000] {ssh.py:283} WARNING - No Host Key Verification. This won't protect against Man-In-The-Middle attacks
[2025-03-11T18:59:06.225+0000] {transport.py:1874} INFO - Connected (version 2.0, client OpenSSH_9.6p1)
[2025-03-11T18:59:06.253+0000] {transport.py:1874} INFO - Authentication (password) successful!
[2025-03-11T18:59:06.254+0000] {ssh.py:460} INFO - Running command: scp -o StrictHostKeyChecking=no /tmp/backup_db.dump Wow-x@192.168.0.47:C:/Temp/
[2025-03-11T18:59:06.513+0000] {ssh.py:501} WARNING - Warning: Permanently added '192.168.0.47' (ED25519) to the list of known hosts.
[2025-03-11T18:59:06.586+0000] {ssh.py:501} WARNING - Permission denied, please try again.
[2025-03-11T18:59:06.594+0000] {ssh.py:501} WARNING - Permission denied, please try again.
[2025-03-11T18:59:06.601+0000] {ssh.py:501} WARNING - Wow-x@192.168.0.47: Permission denied (publickey,password,keyboard-interactive).
[2025-03-11T18:59:06.603+0000] {ssh.py:501} WARNING - scp: Connection closed
[2025-03-11T18:59:06.626+0000] {taskinstance.py:1768} ERROR - Task failed with exception
Traceback (most recent call last):
  File "/home/airflow/.local/lib/python3.7/site-packages/airflow/providers/ssh/operators/ssh.py", line 171, in execute
    result = self.run_ssh_client_command(ssh_client, self.command, context=context)
  File "/home/airflow/.local/lib/python3.7/site-packages/airflow/providers/ssh/operators/ssh.py", line 159, in run_ssh_client_command
    self.raise_for_status(exit_status, agg_stderr, context=context)
  File "/home/airflow/.local/lib/python3.7/site-packages/airflow/providers/ssh/operators/ssh.py", line 152, in raise_for_status
    raise AirflowException(f"SSH operator error: exit status = {exit_status}")
airflow.exceptions.AirflowException: SSH operator error: exit status = 255
[2025-03-11T18:59:06.630+0000] {taskinstance.py:1323} INFO - Marking task as FAILED. dag_id=project2, task_id=transfer_backup, execution_date=20250311T185855, start_date=20250311T185905, end_date=20250311T185906
[2025-03-11T18:59:06.641+0000] {standard_task_runner.py:105} ERROR - Failed to execute job 320 for task transfer_backup (SSH operator error: exit status = 255; 16054)
[2025-03-11T18:59:06.682+0000] {local_task_job.py:208} INFO - Task exited with return code 1
[2025-03-11T18:59:06.699+0000] {taskinstance.py:2578} INFO - 0 downstream tasks scheduled from follow-on schedule check
