[2025-03-11T19:13:08.111+0000] {taskinstance.py:1083} INFO - Dependencies all met for <TaskInstance: project2.transfer_backup manual__2025-03-11T19:12:50.563766+00:00 [queued]>
[2025-03-11T19:13:08.120+0000] {taskinstance.py:1083} INFO - Dependencies all met for <TaskInstance: project2.transfer_backup manual__2025-03-11T19:12:50.563766+00:00 [queued]>
[2025-03-11T19:13:08.121+0000] {taskinstance.py:1279} INFO - 
--------------------------------------------------------------------------------
[2025-03-11T19:13:08.121+0000] {taskinstance.py:1280} INFO - Starting attempt 1 of 1
[2025-03-11T19:13:08.122+0000] {taskinstance.py:1281} INFO - 
--------------------------------------------------------------------------------
[2025-03-11T19:13:08.134+0000] {taskinstance.py:1300} INFO - Executing <Task(SSHOperator): transfer_backup> on 2025-03-11 19:12:50.563766+00:00
[2025-03-11T19:13:08.139+0000] {standard_task_runner.py:55} INFO - Started process 158 to run task
[2025-03-11T19:13:08.141+0000] {standard_task_runner.py:82} INFO - Running: ['***', 'tasks', 'run', 'project2', 'transfer_backup', 'manual__2025-03-11T19:12:50.563766+00:00', '--job-id', '349', '--raw', '--subdir', 'DAGS_FOLDER/project2.py', '--cfg-path', '/tmp/tmpd_p73zp4']
[2025-03-11T19:13:08.142+0000] {standard_task_runner.py:83} INFO - Job 349: Subtask transfer_backup
[2025-03-11T19:13:08.194+0000] {task_command.py:388} INFO - Running <TaskInstance: project2.transfer_backup manual__2025-03-11T19:12:50.563766+00:00 [running]> on host ea6da4397df7
[2025-03-11T19:13:08.253+0000] {taskinstance.py:1509} INFO - Exporting the following env vars:
AIRFLOW_CTX_DAG_OWNER=***
AIRFLOW_CTX_DAG_ID=project2
AIRFLOW_CTX_TASK_ID=transfer_backup
AIRFLOW_CTX_EXECUTION_DATE=2025-03-11T19:12:50.563766+00:00
AIRFLOW_CTX_TRY_NUMBER=1
AIRFLOW_CTX_DAG_RUN_ID=manual__2025-03-11T19:12:50.563766+00:00
[2025-03-11T19:13:08.253+0000] {ssh.py:133} INFO - Creating ssh_client
[2025-03-11T19:13:08.278+0000] {ssh.py:111} INFO - ssh_hook is not provided or invalid. Trying ssh_conn_id to create SSHHook.
[2025-03-11T19:13:08.285+0000] {base.py:73} INFO - Using connection ID 'ssh_vm' for task execution.
[2025-03-11T19:13:08.286+0000] {ssh.py:283} WARNING - No Host Key Verification. This won't protect against Man-In-The-Middle attacks
[2025-03-11T19:13:08.293+0000] {transport.py:1874} INFO - Connected (version 2.0, client OpenSSH_9.6p1)
[2025-03-11T19:13:08.323+0000] {transport.py:1874} INFO - Authentication (password) successful!
[2025-03-11T19:13:08.324+0000] {ssh.py:460} INFO - Running command: scp -o StrictHostKeyChecking=no /tmp/backup_db.dump Wow-x@192.168.0.47:/cygdrive/c/Users/Wow-x/OneDrive/Desktop/
[2025-03-11T19:13:08.612+0000] {ssh.py:501} WARNING - Permission denied, please try again.
[2025-03-11T19:13:08.617+0000] {ssh.py:501} WARNING - Permission denied, please try again.
[2025-03-11T19:13:08.623+0000] {ssh.py:501} WARNING - Wow-x@192.168.0.47: Permission denied (publickey,password,keyboard-interactive).
[2025-03-11T19:13:08.625+0000] {ssh.py:501} WARNING - scp: Connection closed
[2025-03-11T19:13:08.646+0000] {taskinstance.py:1768} ERROR - Task failed with exception
Traceback (most recent call last):
  File "/home/airflow/.local/lib/python3.7/site-packages/airflow/providers/ssh/operators/ssh.py", line 171, in execute
    result = self.run_ssh_client_command(ssh_client, self.command, context=context)
  File "/home/airflow/.local/lib/python3.7/site-packages/airflow/providers/ssh/operators/ssh.py", line 159, in run_ssh_client_command
    self.raise_for_status(exit_status, agg_stderr, context=context)
  File "/home/airflow/.local/lib/python3.7/site-packages/airflow/providers/ssh/operators/ssh.py", line 152, in raise_for_status
    raise AirflowException(f"SSH operator error: exit status = {exit_status}")
airflow.exceptions.AirflowException: SSH operator error: exit status = 255
[2025-03-11T19:13:08.649+0000] {taskinstance.py:1323} INFO - Marking task as FAILED. dag_id=project2, task_id=transfer_backup, execution_date=20250311T191250, start_date=20250311T191308, end_date=20250311T191308
[2025-03-11T19:13:08.660+0000] {standard_task_runner.py:105} ERROR - Failed to execute job 349 for task transfer_backup (SSH operator error: exit status = 255; 158)
[2025-03-11T19:13:08.674+0000] {local_task_job.py:208} INFO - Task exited with return code 1
[2025-03-11T19:13:08.690+0000] {taskinstance.py:2578} INFO - 0 downstream tasks scheduled from follow-on schedule check
